Loading model from meta-llama/Llama-2-13b
Traceback (most recent call last):
  File "/home/khanh/miniforge3/envs/sla_cpt/lib/python3.13/site-packages/huggingface_hub/utils/_http.py", line 409, in hf_raise_for_status
    response.raise_for_status()
    ~~~~~~~~~~~~~~~~~~~~~~~~~^^
  File "/home/khanh/miniforge3/envs/sla_cpt/lib/python3.13/site-packages/requests/models.py", line 1026, in raise_for_status
    raise HTTPError(http_error_msg, response=self)
requests.exceptions.HTTPError: 403 Client Error: Forbidden for url: https://huggingface.co/meta-llama/Llama-2-13b/resolve/main/config.json

The above exception was the direct cause of the following exception:

Traceback (most recent call last):
  File "/home/khanh/miniforge3/envs/sla_cpt/lib/python3.13/site-packages/transformers/utils/hub.py", line 479, in cached_files
    hf_hub_download(
    ~~~~~~~~~~~~~~~^
        path_or_repo_id,
        ^^^^^^^^^^^^^^^^
    ...<10 lines>...
        local_files_only=local_files_only,
        ^^^^^^^^^^^^^^^^^^^^^^^^^^^^^^^^^^
    )
    ^
  File "/home/khanh/miniforge3/envs/sla_cpt/lib/python3.13/site-packages/huggingface_hub/utils/_validators.py", line 114, in _inner_fn
    return fn(*args, **kwargs)
  File "/home/khanh/miniforge3/envs/sla_cpt/lib/python3.13/site-packages/huggingface_hub/file_download.py", line 1010, in hf_hub_download
    return _hf_hub_download_to_cache_dir(
        # Destination
    ...<14 lines>...
        force_download=force_download,
    )
  File "/home/khanh/miniforge3/envs/sla_cpt/lib/python3.13/site-packages/huggingface_hub/file_download.py", line 1117, in _hf_hub_download_to_cache_dir
    _raise_on_head_call_error(head_call_error, force_download, local_files_only)
    ~~~~~~~~~~~~~~~~~~~~~~~~~^^^^^^^^^^^^^^^^^^^^^^^^^^^^^^^^^^^^^^^^^^^^^^^^^^^
  File "/home/khanh/miniforge3/envs/sla_cpt/lib/python3.13/site-packages/huggingface_hub/file_download.py", line 1658, in _raise_on_head_call_error
    raise head_call_error
  File "/home/khanh/miniforge3/envs/sla_cpt/lib/python3.13/site-packages/huggingface_hub/file_download.py", line 1546, in _get_metadata_or_catch_error
    metadata = get_hf_file_metadata(
        url=url, proxies=proxies, timeout=etag_timeout, headers=headers, token=token, endpoint=endpoint
    )
  File "/home/khanh/miniforge3/envs/sla_cpt/lib/python3.13/site-packages/huggingface_hub/utils/_validators.py", line 114, in _inner_fn
    return fn(*args, **kwargs)
  File "/home/khanh/miniforge3/envs/sla_cpt/lib/python3.13/site-packages/huggingface_hub/file_download.py", line 1463, in get_hf_file_metadata
    r = _request_wrapper(
        method="HEAD",
    ...<5 lines>...
        timeout=timeout,
    )
  File "/home/khanh/miniforge3/envs/sla_cpt/lib/python3.13/site-packages/huggingface_hub/file_download.py", line 286, in _request_wrapper
    response = _request_wrapper(
        method=method,
    ...<2 lines>...
        **params,
    )
  File "/home/khanh/miniforge3/envs/sla_cpt/lib/python3.13/site-packages/huggingface_hub/file_download.py", line 310, in _request_wrapper
    hf_raise_for_status(response)
    ~~~~~~~~~~~~~~~~~~~^^^^^^^^^^
  File "/home/khanh/miniforge3/envs/sla_cpt/lib/python3.13/site-packages/huggingface_hub/utils/_http.py", line 426, in hf_raise_for_status
    raise _format(GatedRepoError, message, response) from e
huggingface_hub.errors.GatedRepoError: 403 Client Error. (Request ID: Root=1-68a8edf1-50760af8257ebc965c245d14;cc34e3c1-acda-49fd-a5dc-f6eedebe5e38)

Cannot access gated repo for url https://huggingface.co/meta-llama/Llama-2-13b/resolve/main/config.json.
Access to model meta-llama/Llama-2-13b is restricted and you are not in the authorized list. Visit https://huggingface.co/meta-llama/Llama-2-13b to ask for access.

The above exception was the direct cause of the following exception:

Traceback (most recent call last):
  File "/home/khanh/sla/parameter_analysis/job_scripts/../pa_experiment.py", line 232, in <module>
    main()
    ~~~~^^
  File "/home/khanh/sla/parameter_analysis/job_scripts/../pa_experiment.py", line 229, in main
    compare_parameters(args.base_model_path, args.target_model_path, output_json)
    ~~~~~~~~~~~~~~~~~~^^^^^^^^^^^^^^^^^^^^^^^^^^^^^^^^^^^^^^^^^^^^^^^^^^^^^^^^^^^
  File "/home/khanh/sla/parameter_analysis/job_scripts/../pa_experiment.py", line 148, in compare_parameters
    base_model = load_model(base_model_path, device_map="cpu")
  File "/home/khanh/sla/parameter_analysis/job_scripts/../pa_experiment.py", line 26, in load_model
    return AutoModelForCausalLM.from_pretrained(
           ~~~~~~~~~~~~~~~~~~~~~~~~~~~~~~~~~~~~^
        model_path,
        ^^^^^^^^^^^
        torch_dtype=torch.bfloat16,
        ^^^^^^^^^^^^^^^^^^^^^^^^^^^
        device_map=device_map,
        ^^^^^^^^^^^^^^^^^^^^^^
    )
    ^
  File "/home/khanh/miniforge3/envs/sla_cpt/lib/python3.13/site-packages/transformers/models/auto/auto_factory.py", line 547, in from_pretrained
    config, kwargs = AutoConfig.from_pretrained(
                     ~~~~~~~~~~~~~~~~~~~~~~~~~~^
        pretrained_model_name_or_path,
        ^^^^^^^^^^^^^^^^^^^^^^^^^^^^^^
    ...<4 lines>...
        **kwargs,
        ^^^^^^^^^
    )
    ^
  File "/home/khanh/miniforge3/envs/sla_cpt/lib/python3.13/site-packages/transformers/models/auto/configuration_auto.py", line 1250, in from_pretrained
    config_dict, unused_kwargs = PretrainedConfig.get_config_dict(pretrained_model_name_or_path, **kwargs)
                                 ~~~~~~~~~~~~~~~~~~~~~~~~~~~~~~~~^^^^^^^^^^^^^^^^^^^^^^^^^^^^^^^^^^^^^^^^^
  File "/home/khanh/miniforge3/envs/sla_cpt/lib/python3.13/site-packages/transformers/configuration_utils.py", line 649, in get_config_dict
    config_dict, kwargs = cls._get_config_dict(pretrained_model_name_or_path, **kwargs)
                          ~~~~~~~~~~~~~~~~~~~~^^^^^^^^^^^^^^^^^^^^^^^^^^^^^^^^^^^^^^^^^
  File "/home/khanh/miniforge3/envs/sla_cpt/lib/python3.13/site-packages/transformers/configuration_utils.py", line 708, in _get_config_dict
    resolved_config_file = cached_file(
        pretrained_model_name_or_path,
    ...<10 lines>...
        _commit_hash=commit_hash,
    )
  File "/home/khanh/miniforge3/envs/sla_cpt/lib/python3.13/site-packages/transformers/utils/hub.py", line 321, in cached_file
    file = cached_files(path_or_repo_id=path_or_repo_id, filenames=[filename], **kwargs)
  File "/home/khanh/miniforge3/envs/sla_cpt/lib/python3.13/site-packages/transformers/utils/hub.py", line 543, in cached_files
    raise OSError(
    ...<2 lines>...
    ) from e
OSError: You are trying to access a gated repo.
Make sure to have access to it at https://huggingface.co/meta-llama/Llama-2-13b.
403 Client Error. (Request ID: Root=1-68a8edf1-50760af8257ebc965c245d14;cc34e3c1-acda-49fd-a5dc-f6eedebe5e38)

Cannot access gated repo for url https://huggingface.co/meta-llama/Llama-2-13b/resolve/main/config.json.
Access to model meta-llama/Llama-2-13b is restricted and you are not in the authorized list. Visit https://huggingface.co/meta-llama/Llama-2-13b to ask for access.
